package HazzaMod;
import java.util.Random;

import net.minecraft.src.*;

public class WorldGenAncientRuins extends WorldGenerator
{
	public WorldGenAncientRuins()
	{		
	}
	
	public boolean generate(World world, Random random, int x, int y, int z)
    {
		//Lazy Mode Engaged!
		if(world.getBlockId(x, y , z) == 0){
		world.setBlockWithNotify(x, y, z, HazzaMod.Cloud.blockID);
		world.setBlockWithNotify(x, y + 1, z, HazzaMod.AncientBricks.blockID);
		world.setBlockWithNotify(x, y + 2, z, HazzaMod.ChestOfAlexander.blockID);
		world.setBlockWithNotify(x, y + 3, z, HazzaMod.AncientBricks.blockID);
		world.setBlockWithNotify(x, y + 4, z, HazzaMod.TazniteSpawner.blockID);
		world.setBlockWithNotify(x + 1, y + 3, z, HazzaMod.PrometheusGrass.blockID);
		world.setBlockWithNotify(x + 2, y + 3, z, HazzaMod.PrometheusGrass.blockID);
		world.setBlockWithNotify(x - 1, y + 3, z, HazzaMod.PrometheusGrass.blockID);
		world.setBlockWithNotify(x - 2, y + 3, z, HazzaMod.PrometheusGrass.blockID);
		world.setBlockWithNotify(x, y + 3, z + 1, HazzaMod.PrometheusGrass.blockID);
		world.setBlockWithNotify(x, y + 3, z + 2, HazzaMod.PrometheusGrass.blockID);
		world.setBlockWithNotify(x, y + 3, z - 1, HazzaMod.PrometheusGrass.blockID);
		world.setBlockWithNotify(x, y + 3, z - 2, HazzaMod.PrometheusGrass.blockID);
		world.setBlockWithNotify(x + 1, y + 3, z + 1, HazzaMod.PrometheusGrass.blockID);
		world.setBlockWithNotify(x + 1, y + 3, z + 2, HazzaMod.PrometheusGrass.blockID);
		world.setBlockWithNotify(x + 2, y + 3, z + 1, HazzaMod.PrometheusGrass.blockID);
		world.setBlockWithNotify(x + 2, y + 3, z + 2, HazzaMod.PrometheusGrass.blockID);
		world.setBlockWithNotify(x + 1, y + 3, z - 1, HazzaMod.PrometheusGrass.blockID);
		world.setBlockWithNotify(x + 1, y + 3, z - 2, HazzaMod.PrometheusGrass.blockID);
		world.setBlockWithNotify(x + 2, y + 3, z - 1, HazzaMod.PrometheusGrass.blockID);
		world.setBlockWithNotify(x + 2, y + 3, z - 2, HazzaMod.PrometheusGrass.blockID);
		world.setBlockWithNotify(x - 1, y + 3, z + 1, HazzaMod.PrometheusGrass.blockID);
		world.setBlockWithNotify(x - 1, y + 3, z + 2, HazzaMod.PrometheusGrass.blockID);
		world.setBlockWithNotify(x - 2, y + 3, z + 1, HazzaMod.PrometheusGrass.blockID);
		world.setBlockWithNotify(x - 2, y + 3, z + 2, HazzaMod.PrometheusGrass.blockID);
		world.setBlockWithNotify(x - 1, y + 3, z - 1, HazzaMod.PrometheusGrass.blockID);
		world.setBlockWithNotify(x - 1, y + 3, z - 2, HazzaMod.PrometheusGrass.blockID);
		world.setBlockWithNotify(x - 2, y + 3, z - 1, HazzaMod.PrometheusGrass.blockID);
		world.setBlockWithNotify(x - 2, y + 3, z - 2, HazzaMod.PrometheusGrass.blockID);
		world.setBlockWithNotify(x + 3, y + 3, z + 3, HazzaMod.Cloud.blockID);
		world.setBlockWithNotify(x + 3, y + 3, z + 2, HazzaMod.Cloud.blockID);
		world.setBlockWithNotify(x + 3, y + 3, z + 1, HazzaMod.Cloud.blockID);
		world.setBlockWithNotify(x + 3, y + 3, z, HazzaMod.Cloud.blockID);
		world.setBlockWithNotify(x + 3, y + 3, z - 1, HazzaMod.Cloud.blockID);
		world.setBlockWithNotify(x + 3, y + 3, z - 2, HazzaMod.Cloud.blockID);
		world.setBlockWithNotify(x + 3, y + 3, z - 3, HazzaMod.Cloud.blockID);
		world.setBlockWithNotify(x + 3, y + 3, z + 3, HazzaMod.Cloud.blockID);
		world.setBlockWithNotify(x + 3, y + 3, z - 3, HazzaMod.Cloud.blockID);
		world.setBlockWithNotify(x + 2, y + 3, z - 3, HazzaMod.Cloud.blockID);
		world.setBlockWithNotify(x + 1, y + 3, z - 3, HazzaMod.Cloud.blockID);
		world.setBlockWithNotify(x , y + 3, z - 3, HazzaMod.Cloud.blockID);
		world.setBlockWithNotify(x - 1, y + 3, z - 3, HazzaMod.Cloud.blockID);
		world.setBlockWithNotify(x - 2, y + 3, z - 3, HazzaMod.Cloud.blockID);
		world.setBlockWithNotify(x - 3, y + 3, z - 3, HazzaMod.Cloud.blockID);
		world.setBlockWithNotify(x - 3, y + 3, z - 3, HazzaMod.Cloud.blockID);
		world.setBlockWithNotify(x - 3, y + 3, z - 2, HazzaMod.Cloud.blockID);
		world.setBlockWithNotify(x - 3, y + 3, z - 1, HazzaMod.Cloud.blockID);
		world.setBlockWithNotify(x - 3, y + 3, z , HazzaMod.Cloud.blockID);
		world.setBlockWithNotify(x - 3, y + 3, z + 1, HazzaMod.Cloud.blockID);
		world.setBlockWithNotify(x - 3, y + 3, z + 2, HazzaMod.Cloud.blockID);
		world.setBlockWithNotify(x - 3, y + 3, z + 3, HazzaMod.Cloud.blockID);
		world.setBlockWithNotify(x - 3, y + 3, z + 3, HazzaMod.Cloud.blockID);
		world.setBlockWithNotify(x - 3, y + 3, z + 2, HazzaMod.Cloud.blockID);
		world.setBlockWithNotify(x - 3, y + 3, z + 3, HazzaMod.Cloud.blockID);
		world.setBlockWithNotify(x - 2, y + 3, z + 3, HazzaMod.Cloud.blockID);
		world.setBlockWithNotify(x - 1, y + 3, z + 3, HazzaMod.Cloud.blockID);
		world.setBlockWithNotify(x, y + 3, z + 3, HazzaMod.Cloud.blockID);
		world.setBlockWithNotify(x , y + 3, z + 3, HazzaMod.Cloud.blockID);
		world.setBlockWithNotify(x + 2, y + 3, z + 3, HazzaMod.Cloud.blockID);
		world.setBlockWithNotify(x + 3, y + 4, z + 3, HazzaMod.AncientBricks.blockID);
		world.setBlockWithNotify(x + 3, y + 4, z + 2, HazzaMod.AncientBricks.blockID);
		world.setBlockWithNotify(x + 3, y + 4, z + 1, HazzaMod.AncientBricks.blockID);
		world.setBlockWithNotify(x + 3, y + 4, z, HazzaMod.AncientBricks.blockID);
		world.setBlockWithNotify(x + 3, y + 4, z - 1, HazzaMod.AncientBricks.blockID);
		world.setBlockWithNotify(x + 3, y + 4, z - 2, HazzaMod.AncientBricks.blockID);
		world.setBlockWithNotify(x + 3, y + 4, z - 3, HazzaMod.AncientBricks.blockID);
		world.setBlockWithNotify(x + 3, y + 4, z + 3, HazzaMod.AncientBricks.blockID);
		world.setBlockWithNotify(x + 3, y + 4, z - 3, HazzaMod.AncientBricks.blockID);
		world.setBlockWithNotify(x + 2, y + 4, z - 3, HazzaMod.AncientBricks.blockID);
		world.setBlockWithNotify(x    , y + 4, z - 3, HazzaMod.AncientBricks.blockID);
		world.setBlockWithNotify(x - 1, y + 4, z - 3, HazzaMod.AncientBricks.blockID);
		world.setBlockWithNotify(x - 2, y + 4, z - 3, HazzaMod.AncientBricks.blockID);
		world.setBlockWithNotify(x - 3, y + 4, z - 3, HazzaMod.AncientBricks.blockID);
		world.setBlockWithNotify(x - 3, y + 4, z - 3, HazzaMod.AncientBricks.blockID);
		world.setBlockWithNotify(x - 3, y + 4, z - 2, HazzaMod.AncientBricks.blockID);
		world.setBlockWithNotify(x - 3, y + 4, z - 1, HazzaMod.AncientBricks.blockID);
		world.setBlockWithNotify(x - 3, y + 4, z    , HazzaMod.AncientBricks.blockID);
		world.setBlockWithNotify(x - 3, y + 4, z + 1, HazzaMod.AncientBricks.blockID);
		world.setBlockWithNotify(x - 3, y + 4, z + 2, HazzaMod.AncientBricks.blockID);
		world.setBlockWithNotify(x - 3, y + 4, z + 3, HazzaMod.AncientBricks.blockID);
		world.setBlockWithNotify(x - 3, y + 4, z + 3 ,HazzaMod.AncientBricks.blockID);
		world.setBlockWithNotify(x - 3, y + 4, z + 2, HazzaMod.AncientBricks.blockID);
		world.setBlockWithNotify(x - 3, y + 4, z + 3, HazzaMod.AncientBricks.blockID);
		world.setBlockWithNotify(x - 2, y + 4, z + 3, HazzaMod.AncientBricks.blockID);
		world.setBlockWithNotify(x - 1, y + 4, z + 3, HazzaMod.AncientBricks.blockID);
		world.setBlockWithNotify(x    , y + 4, z + 3, HazzaMod.AncientBricks.blockID);
		world.setBlockWithNotify(x    , y + 4, z + 3, HazzaMod.AncientBricks.blockID);
		world.setBlockWithNotify(x + 2, y + 4, z + 3, HazzaMod.AncientBricks.blockID);
		world.setBlockWithNotify(x + 3, y + 5, z + 3, HazzaMod.AncientBricks.blockID);
		world.setBlockWithNotify(x + 3, y + 5, z + 2, HazzaMod.AncientBricks.blockID);
		world.setBlockWithNotify(x + 3, y + 5, z + 1, HazzaMod.AncientBricks.blockID);
		world.setBlockWithNotify(x + 3, y + 5, z, HazzaMod.AncientBricks.blockID);
		world.setBlockWithNotify(x + 3, y + 5, z - 1, HazzaMod.AncientBricks.blockID);
		world.setBlockWithNotify(x + 3, y + 5, z - 2, HazzaMod.AncientBricks.blockID);
		world.setBlockWithNotify(x + 3, y + 5, z - 3, HazzaMod.AncientBricks.blockID);
		world.setBlockWithNotify(x + 3, y + 5, z + 3, HazzaMod.AncientBricks.blockID);
		world.setBlockWithNotify(x + 3, y + 5, z - 3, HazzaMod.AncientBricks.blockID);
		world.setBlockWithNotify(x + 2, y + 5, z - 3, HazzaMod.AncientBricks.blockID);
		world.setBlockWithNotify(x + 1, y + 5, z - 3, HazzaMod.AncientBricks.blockID);
		world.setBlockWithNotify(x , y + 5, z - 3, HazzaMod.AncientBricks.blockID);
		world.setBlockWithNotify(x - 1, y + 5, z - 3, HazzaMod.AncientBricks.blockID);
		world.setBlockWithNotify(x - 2, y + 5, z - 3,HazzaMod.AncientBricks.blockID);
		world.setBlockWithNotify(x - 3, y + 5, z - 3, HazzaMod.AncientBricks.blockID);
		world.setBlockWithNotify(x - 3, y + 5, z - 3, HazzaMod.AncientBricks.blockID);
		world.setBlockWithNotify(x - 3, y + 5, z - 2, HazzaMod.AncientBricks.blockID);
		world.setBlockWithNotify(x - 3, y + 5, z - 1, HazzaMod.AncientBricks.blockID);
		world.setBlockWithNotify(x - 3, y + 5, z , HazzaMod.AncientBricks.blockID);
		world.setBlockWithNotify(x - 3, y + 5, z + 1, HazzaMod.AncientBricks.blockID);
		world.setBlockWithNotify(x - 3, y + 5, z + 2,HazzaMod.AncientBricks.blockID);
		world.setBlockWithNotify(x - 3, y + 5, z + 3,HazzaMod.AncientBricks.blockID);
		world.setBlockWithNotify(x - 3, y + 5, z + 3,HazzaMod.AncientBricks.blockID);
		world.setBlockWithNotify(x - 3, y + 5, z + 2, HazzaMod.AncientBricks.blockID);
		world.setBlockWithNotify(x - 3, y + 5, z + 3, HazzaMod.AncientBricks.blockID);
		world.setBlockWithNotify(x - 2, y + 5, z + 3, HazzaMod.AncientBricks.blockID);
		world.setBlockWithNotify(x - 1, y + 5, z + 3, HazzaMod.AncientBricks.blockID);
		world.setBlockWithNotify(x, y + 5, z + 3, HazzaMod.AncientBricks.blockID);
		world.setBlockWithNotify(x , y + 5, z + 3, HazzaMod.AncientBricks.blockID);
		world.setBlockWithNotify(x + 2, y + 5, z + 3, HazzaMod.AncientBricks.blockID);
		world.setBlockWithNotify(x + 1, y + 4, z - 3, HazzaMod.AncientBricks.blockID);
		world.setBlockWithNotify(x + 1, y + 3, z - 3, HazzaMod.Cloud.blockID);
		world.setBlockWithNotify(x + 1, y + 3, z + 3, HazzaMod.Cloud.blockID);
		world.setBlockWithNotify(x + 1, y + 4, z + 3, HazzaMod.AncientBricks.blockID);
		world.setBlockWithNotify(x + 1, y + 5, z + 3, HazzaMod.AncientBricks.blockID);
		world.setBlockWithNotify(x    , y + 8, z  + 1, HazzaMod.Cloud.blockID);
		world.setBlockWithNotify(x    , y + 8, z  + 2, HazzaMod.Cloud.blockID);
		world.setBlockWithNotify(x    , y + 8, z  + 3, HazzaMod.Cloud.blockID);
		world.setBlockWithNotify(x    , y + 8, z  - 1, HazzaMod.Cloud.blockID);
		world.setBlockWithNotify(x    , y + 8, z  - 3, HazzaMod.Cloud.blockID);
		world.setBlockWithNotify(x    , y + 8, z  - 2, HazzaMod.Cloud.blockID);
		world.setBlockWithNotify(x    , y + 8, z     , HazzaMod.Cloud.blockID);
		world.setBlockWithNotify(x  + 1  , y + 7, z  + 1, HazzaMod.Cloud.blockID);
		world.setBlockWithNotify(x  + 1  , y + 7, z  + 2, HazzaMod.Cloud.blockID);
		world.setBlockWithNotify(x  + 1  , y + 7, z  + 3, HazzaMod.Cloud.blockID);
		world.setBlockWithNotify(x  + 1  , y + 7, z  - 1, HazzaMod.Cloud.blockID);
		world.setBlockWithNotify(x  + 1  , y + 7, z  - 3, HazzaMod.Cloud.blockID);
		world.setBlockWithNotify(x  + 1  , y + 7, z  - 2, HazzaMod.Cloud.blockID);
		world.setBlockWithNotify(x  + 1  , y + 7, z     , HazzaMod.Cloud.blockID);
		world.setBlockWithNotify(x  - 1  , y + 7, z  + 1, HazzaMod.Cloud.blockID);
		world.setBlockWithNotify(x  - 1  , y + 7, z  + 2, HazzaMod.Cloud.blockID);
		world.setBlockWithNotify(x  - 1  , y + 7, z  + 3, HazzaMod.Cloud.blockID);
		world.setBlockWithNotify(x  - 1  , y + 7, z  - 1, HazzaMod.Cloud.blockID);
		world.setBlockWithNotify(x  - 1  , y + 7, z  - 3, HazzaMod.Cloud.blockID);
		world.setBlockWithNotify(x  - 1  , y + 7, z  - 2, HazzaMod.Cloud.blockID);
		world.setBlockWithNotify(x  - 1  , y + 7, z     , HazzaMod.Cloud.blockID);
		world.setBlockWithNotify(x  + 2  , y + 6, z  + 1, HazzaMod.Cloud.blockID);
		world.setBlockWithNotify(x  + 2  , y + 6, z  + 2, HazzaMod.Cloud.blockID);
		world.setBlockWithNotify(x  + 2  , y + 6, z  + 3, HazzaMod.Cloud.blockID);
		world.setBlockWithNotify(x  + 2  , y + 6, z  - 1, HazzaMod.Cloud.blockID);
		world.setBlockWithNotify(x  + 2  , y + 6, z  - 3, HazzaMod.Cloud.blockID);
		world.setBlockWithNotify(x  + 2  , y + 6, z  - 2, HazzaMod.Cloud.blockID);
		world.setBlockWithNotify(x  + 2  , y + 6, z     , HazzaMod.Cloud.blockID);
		world.setBlockWithNotify(x  - 2  , y + 6, z  + 1, HazzaMod.Cloud.blockID);
		world.setBlockWithNotify(x  - 2  , y + 6, z  + 2, HazzaMod.Cloud.blockID);
		world.setBlockWithNotify(x  - 2  , y + 6, z  + 3, HazzaMod.Cloud.blockID);
		world.setBlockWithNotify(x  - 2  , y + 6, z  - 1, HazzaMod.Cloud.blockID);
		world.setBlockWithNotify(x  - 2  , y + 6, z  - 3, HazzaMod.Cloud.blockID);
		world.setBlockWithNotify(x  - 2  , y + 6, z  - 2, HazzaMod.Cloud.blockID);
		world.setBlockWithNotify(x  - 2  , y + 6, z     , HazzaMod.Cloud.blockID);
		world.setBlockWithNotify(x  - 1  , y + 6, z + 3  , HazzaMod.Cloud.blockID);
		world.setBlockWithNotify(x    , y + 6, z + 3  , HazzaMod.Cloud.blockID);
		world.setBlockWithNotify(x    , y + 7, z + 3  , HazzaMod.Cloud.blockID);
		world.setBlockWithNotify(x  + 1  , y + 6, z + 3  , HazzaMod.Cloud.blockID);
		world.setBlockWithNotify(x  - 1  , y + 6, z - 3  , HazzaMod.Cloud.blockID);
		world.setBlockWithNotify(x    , y + 6, z - 3  , HazzaMod.Cloud.blockID);
		world.setBlockWithNotify(x    , y + 7, z - 3  , HazzaMod.Cloud.blockID);
		world.setBlockWithNotify(x  + 1  , y + 6, z - 3  , HazzaMod.Cloud.blockID);
		
		//Start Floor
		world.setBlockWithNotify(x - 1  , y + 2, z - 3  , HazzaMod.Cloud.blockID);
		world.setBlockWithNotify(x - 2  , y + 2, z - 3  , HazzaMod.Cloud.blockID);
		world.setBlockWithNotify(x - 3  , y + 2, z - 3  , HazzaMod.Cloud.blockID);
		world.setBlockWithNotify(x      , y + 2, z - 3  , HazzaMod.Cloud.blockID);
		world.setBlockWithNotify(x + 1  , y + 2, z - 3  , HazzaMod.Cloud.blockID);
		world.setBlockWithNotify(x + 2  , y + 2, z - 3  , HazzaMod.Cloud.blockID);
		world.setBlockWithNotify(x + 3  , y + 2, z - 3  , HazzaMod.Cloud.blockID);
		world.setBlockWithNotify(x - 1  , y + 2, z - 2  , HazzaMod.Cloud.blockID);
		world.setBlockWithNotify(x - 2  , y + 2, z - 2  , HazzaMod.Cloud.blockID);
		world.setBlockWithNotify(x - 3  , y + 2, z - 2  , HazzaMod.Cloud.blockID);
		world.setBlockWithNotify(x      , y + 2, z - 2  , HazzaMod.Cloud.blockID);
		world.setBlockWithNotify(x + 1  , y + 2, z - 2  , HazzaMod.Cloud.blockID);
		world.setBlockWithNotify(x + 2  , y + 2, z - 2  , HazzaMod.Cloud.blockID);
		world.setBlockWithNotify(x + 3  , y + 2, z - 2  , HazzaMod.Cloud.blockID);
		world.setBlockWithNotify(x - 1  , y + 2, z - 1  , HazzaMod.Cloud.blockID);
		world.setBlockWithNotify(x - 2  , y + 2, z - 1  , HazzaMod.Cloud.blockID);
		world.setBlockWithNotify(x - 3  , y + 2, z - 1  , HazzaMod.Cloud.blockID);
		world.setBlockWithNotify(x      , y + 2, z - 1  , HazzaMod.Cloud.blockID);
		world.setBlockWithNotify(x + 1  , y + 2, z - 1  , HazzaMod.Cloud.blockID);
		world.setBlockWithNotify(x + 2  , y + 2, z - 1  , HazzaMod.Cloud.blockID);
		world.setBlockWithNotify(x + 3  , y + 2, z - 1  , HazzaMod.Cloud.blockID);
		world.setBlockWithNotify(x - 1  , y + 2, z - 0  , HazzaMod.Cloud.blockID);
		world.setBlockWithNotify(x - 2  , y + 2, z - 0  , HazzaMod.Cloud.blockID);
		world.setBlockWithNotify(x - 3  , y + 2, z - 0  , HazzaMod.Cloud.blockID);
		world.setBlockWithNotify(x + 1  , y + 2, z - 0  , HazzaMod.Cloud.blockID);
		world.setBlockWithNotify(x + 2  , y + 2, z - 0  , HazzaMod.Cloud.blockID);
		world.setBlockWithNotify(x + 3  , y + 2, z - 0  , HazzaMod.Cloud.blockID);
		world.setBlockWithNotify(x - 1  , y + 2, z + 1  , HazzaMod.Cloud.blockID);
		world.setBlockWithNotify(x - 2  , y + 2, z + 1  , HazzaMod.Cloud.blockID);
		world.setBlockWithNotify(x - 3  , y + 2, z + 1  , HazzaMod.Cloud.blockID);
		world.setBlockWithNotify(x      , y + 2, z + 1  , HazzaMod.Cloud.blockID);
		world.setBlockWithNotify(x + 1  , y + 2, z + 1  , HazzaMod.Cloud.blockID);
		world.setBlockWithNotify(x + 2  , y + 2, z + 1  , HazzaMod.Cloud.blockID);
		world.setBlockWithNotify(x + 3  , y + 2, z + 1  , HazzaMod.Cloud.blockID);		
		world.setBlockWithNotify(x - 1  , y + 2, z + 2  , HazzaMod.Cloud.blockID);
		world.setBlockWithNotify(x - 2  , y + 2, z + 2  , HazzaMod.Cloud.blockID);
		world.setBlockWithNotify(x - 3  , y + 2, z + 2  , HazzaMod.Cloud.blockID);
		world.setBlockWithNotify(x      , y + 2, z + 2  , HazzaMod.Cloud.blockID);
		world.setBlockWithNotify(x + 1  , y + 2, z + 2  , HazzaMod.Cloud.blockID);
		world.setBlockWithNotify(x + 2  , y + 2, z + 2  , HazzaMod.Cloud.blockID);
		world.setBlockWithNotify(x + 3  , y + 2, z + 2  , HazzaMod.Cloud.blockID);		
		world.setBlockWithNotify(x - 1  , y + 2, z + 3  , HazzaMod.Cloud.blockID);
		world.setBlockWithNotify(x - 2  , y + 2, z + 3  , HazzaMod.Cloud.blockID);
		world.setBlockWithNotify(x - 3  , y + 2, z + 3  , HazzaMod.Cloud.blockID);
		world.setBlockWithNotify(x      , y + 2, z + 3  , HazzaMod.Cloud.blockID);
		world.setBlockWithNotify(x + 1  , y + 2, z + 3  , HazzaMod.Cloud.blockID);
		world.setBlockWithNotify(x + 2  , y + 2, z + 3  , HazzaMod.Cloud.blockID);
		world.setBlockWithNotify(x + 3  , y + 2, z + 3  , HazzaMod.Cloud.blockID);		
		world.setBlockWithNotify(x - 1  , y + 1, z - 3  , HazzaMod.Cloud.blockID);
		world.setBlockWithNotify(x - 2  , y + 1, z - 3  , HazzaMod.Cloud.blockID);
		world.setBlockWithNotify(x - 3  , y + 1, z - 3  , HazzaMod.Cloud.blockID);
		world.setBlockWithNotify(x      , y + 1, z - 3  , HazzaMod.Cloud.blockID);
		world.setBlockWithNotify(x + 1  , y + 1, z - 3  , HazzaMod.Cloud.blockID);
		world.setBlockWithNotify(x + 2  , y + 1, z - 3  , HazzaMod.Cloud.blockID);
		world.setBlockWithNotify(x + 3  , y + 1, z - 3  , HazzaMod.Cloud.blockID);
		world.setBlockWithNotify(x - 1  , y + 1, z - 2  , HazzaMod.Cloud.blockID);
		world.setBlockWithNotify(x - 2  , y + 1, z - 2  , HazzaMod.Cloud.blockID);
		world.setBlockWithNotify(x - 3  , y + 1, z - 2  , HazzaMod.Cloud.blockID);
		world.setBlockWithNotify(x      , y + 1, z - 2  , HazzaMod.Cloud.blockID);
		world.setBlockWithNotify(x + 1  , y + 1, z - 2  , HazzaMod.Cloud.blockID);
		world.setBlockWithNotify(x + 2  , y + 1, z - 2  , HazzaMod.Cloud.blockID);
		world.setBlockWithNotify(x + 3  , y + 1, z - 2  , HazzaMod.Cloud.blockID);
		world.setBlockWithNotify(x - 1  , y + 1, z - 1  , HazzaMod.Cloud.blockID);
		world.setBlockWithNotify(x - 2  , y + 1, z - 1  , HazzaMod.Cloud.blockID);
		world.setBlockWithNotify(x - 3  , y + 1, z - 1  , HazzaMod.Cloud.blockID);
		world.setBlockWithNotify(x      , y + 1, z - 1  , HazzaMod.Cloud.blockID);
		world.setBlockWithNotify(x + 1  , y + 1, z - 1  , HazzaMod.Cloud.blockID);
		world.setBlockWithNotify(x + 2  , y + 1, z - 1  , HazzaMod.Cloud.blockID);
		world.setBlockWithNotify(x + 3  , y + 1, z - 1  , HazzaMod.Cloud.blockID);
		world.setBlockWithNotify(x - 1  , y + 1, z - 0  , HazzaMod.Cloud.blockID);
		world.setBlockWithNotify(x - 2  , y + 1, z - 0  , HazzaMod.Cloud.blockID);
		world.setBlockWithNotify(x - 3  , y + 1, z - 0  , HazzaMod.Cloud.blockID);
		world.setBlockWithNotify(x + 1  , y + 1, z - 0  , HazzaMod.Cloud.blockID);
		world.setBlockWithNotify(x + 2  , y + 1, z - 0  , HazzaMod.Cloud.blockID);
		world.setBlockWithNotify(x + 3  , y + 1, z - 0  , HazzaMod.Cloud.blockID);
		world.setBlockWithNotify(x - 1  , y + 1, z + 1  , HazzaMod.Cloud.blockID);
		world.setBlockWithNotify(x - 2  , y + 1, z + 1  , HazzaMod.Cloud.blockID);
		world.setBlockWithNotify(x - 3  , y + 1, z + 1  , HazzaMod.Cloud.blockID);
		world.setBlockWithNotify(x      , y + 1, z + 1  , HazzaMod.Cloud.blockID);
		world.setBlockWithNotify(x + 1  , y + 1, z + 1  , HazzaMod.Cloud.blockID);
		world.setBlockWithNotify(x + 2  , y + 1, z + 1  , HazzaMod.Cloud.blockID);
		world.setBlockWithNotify(x + 3  , y + 1, z + 1  , HazzaMod.Cloud.blockID);
		world.setBlockWithNotify(x - 1  , y + 1, z + 2  , HazzaMod.Cloud.blockID);
		world.setBlockWithNotify(x - 2  , y + 1, z + 2  , HazzaMod.Cloud.blockID);
		world.setBlockWithNotify(x - 3  , y + 1, z + 2  , HazzaMod.Cloud.blockID);
		world.setBlockWithNotify(x      , y + 1, z + 2  , HazzaMod.Cloud.blockID);
		world.setBlockWithNotify(x + 1  , y + 1, z + 2  , HazzaMod.Cloud.blockID);
		world.setBlockWithNotify(x + 2  , y + 1, z + 2  , HazzaMod.Cloud.blockID);
		world.setBlockWithNotify(x + 3  , y + 1, z + 2  , HazzaMod.Cloud.blockID);	
		world.setBlockWithNotify(x - 1  , y + 1, z + 3  , HazzaMod.Cloud.blockID);
		world.setBlockWithNotify(x - 2  , y + 1, z + 3  , HazzaMod.Cloud.blockID);
		world.setBlockWithNotify(x - 3  , y + 1, z + 3  , HazzaMod.Cloud.blockID);
		world.setBlockWithNotify(x      , y + 1, z + 3  , HazzaMod.Cloud.blockID);
		world.setBlockWithNotify(x + 1  , y + 1, z + 3  , HazzaMod.Cloud.blockID);
		world.setBlockWithNotify(x + 2  , y + 1, z + 3  , HazzaMod.Cloud.blockID);
		world.setBlockWithNotify(x + 3  , y + 1, z + 3  , HazzaMod.Cloud.blockID);
		world.setBlockWithNotify(x - 1  , y + 0, z - 3  , HazzaMod.Cloud.blockID);
		world.setBlockWithNotify(x - 2  , y + 0, z - 3  , HazzaMod.Cloud.blockID);
		world.setBlockWithNotify(x - 3  , y + 0, z - 3  , HazzaMod.Cloud.blockID);
		world.setBlockWithNotify(x      , y + 0, z - 3  , HazzaMod.Cloud.blockID);
		world.setBlockWithNotify(x + 1  , y + 0, z - 3  , HazzaMod.Cloud.blockID);
		world.setBlockWithNotify(x + 2  , y + 0, z - 3  , HazzaMod.Cloud.blockID);
		world.setBlockWithNotify(x + 3  , y + 0, z - 3  , HazzaMod.Cloud.blockID);
		world.setBlockWithNotify(x - 1  , y + 0, z - 2  , HazzaMod.Cloud.blockID);
		world.setBlockWithNotify(x - 2  , y + 0, z - 2  , HazzaMod.Cloud.blockID);
		world.setBlockWithNotify(x - 3  , y + 0, z - 2  , HazzaMod.Cloud.blockID);
		world.setBlockWithNotify(x      , y + 0, z - 2  , HazzaMod.Cloud.blockID);
		world.setBlockWithNotify(x + 1  , y + 0, z - 2  , HazzaMod.Cloud.blockID);
		world.setBlockWithNotify(x + 2  , y + 0, z - 2  , HazzaMod.Cloud.blockID);
		world.setBlockWithNotify(x + 3  , y + 0, z - 2  , HazzaMod.Cloud.blockID);
		world.setBlockWithNotify(x - 1  , y + 0, z - 1  , HazzaMod.Cloud.blockID);
		world.setBlockWithNotify(x - 2  , y + 0, z - 1  , HazzaMod.Cloud.blockID);
		world.setBlockWithNotify(x - 3  , y + 0, z - 1  , HazzaMod.Cloud.blockID);
		world.setBlockWithNotify(x      , y + 0, z - 1  , HazzaMod.Cloud.blockID);
		world.setBlockWithNotify(x + 1  , y + 0, z - 1  , HazzaMod.Cloud.blockID);
		world.setBlockWithNotify(x + 2  , y + 0, z - 1  , HazzaMod.Cloud.blockID);
		world.setBlockWithNotify(x + 3  , y + 0, z - 1  , HazzaMod.Cloud.blockID);
		world.setBlockWithNotify(x - 1  , y + 0, z - 0  , HazzaMod.Cloud.blockID);
		world.setBlockWithNotify(x - 2  , y + 0, z - 0  , HazzaMod.Cloud.blockID);
		world.setBlockWithNotify(x - 3  , y + 0, z - 0  , HazzaMod.Cloud.blockID);
		world.setBlockWithNotify(x + 1  , y + 0, z - 0  , HazzaMod.Cloud.blockID);
		world.setBlockWithNotify(x + 2  , y + 0, z - 0  , HazzaMod.Cloud.blockID);
		world.setBlockWithNotify(x + 3  , y + 0, z - 0  , HazzaMod.Cloud.blockID);
		world.setBlockWithNotify(x - 1  , y + 0, z + 1  , HazzaMod.Cloud.blockID);
		world.setBlockWithNotify(x - 2  , y + 0, z + 1  , HazzaMod.Cloud.blockID);
		world.setBlockWithNotify(x - 3  , y + 0, z + 1  , HazzaMod.Cloud.blockID);
		world.setBlockWithNotify(x      , y + 0, z + 1  , HazzaMod.Cloud.blockID);
		world.setBlockWithNotify(x + 1  , y + 0, z + 1  , HazzaMod.Cloud.blockID);
		world.setBlockWithNotify(x + 2  , y + 0, z + 1  , HazzaMod.Cloud.blockID);
		world.setBlockWithNotify(x + 3  , y + 0, z + 1  , HazzaMod.Cloud.blockID);
		world.setBlockWithNotify(x - 1  , y + 0, z + 2  , HazzaMod.Cloud.blockID);
		world.setBlockWithNotify(x - 2  , y + 0, z + 2  , HazzaMod.Cloud.blockID);
		world.setBlockWithNotify(x - 3  , y + 0, z + 2  , HazzaMod.Cloud.blockID);
		world.setBlockWithNotify(x      , y + 0, z + 2  , HazzaMod.Cloud.blockID);
		world.setBlockWithNotify(x + 1  , y + 0, z + 2  , HazzaMod.Cloud.blockID);
		world.setBlockWithNotify(x + 2  , y + 0, z + 2  , HazzaMod.Cloud.blockID);
		world.setBlockWithNotify(x + 3  , y + 0, z + 2  , HazzaMod.Cloud.blockID);
		world.setBlockWithNotify(x - 1  , y + 0, z + 3  , HazzaMod.Cloud.blockID);
		world.setBlockWithNotify(x - 2  , y + 0, z + 3  , HazzaMod.Cloud.blockID);
		world.setBlockWithNotify(x - 3  , y + 0, z + 3  , HazzaMod.Cloud.blockID);
		world.setBlockWithNotify(x      , y + 0, z + 3  , HazzaMod.Cloud.blockID);
		world.setBlockWithNotify(x + 1  , y + 0, z + 3  , HazzaMod.Cloud.blockID);
		world.setBlockWithNotify(x + 2  , y + 0, z + 3  , HazzaMod.Cloud.blockID);
		world.setBlockWithNotify(x + 3  , y + 0, z + 3  , HazzaMod.Cloud.blockID);
		
		return true;
    }
		return false;
	
}
	}
